Sun Apr 23 20:35:24 2023 [31m[49m#1[39m –¶–°–ö–ê –• –ú—Å–∫: [31m[49mMain: HTTPSConnectionPool(host='tickets.cska-hockey.ru', port=443): Max retries exceeded with url: / (Caused by ProxyError('Cannot connect to proxy.', OSError('Tunnel connection failed: 407 Proxy Authentication Required',)))[39mSun Apr 23 20:35:24 2023 [31m[49m#1[39m –¶–°–ö–ê –• –ú—Å–∫: [31m[49mMain: HTTPSConnectionPool(host='tickets.cska-hockey.ru', port=443): Max retries exceeded with url: / (Caused by ProxyError('Cannot connect to proxy.', OSError('Tunnel connection failed: 407 Proxy Authentication Required',)))[39m
[31m[49mTraceback (most recent call last):
  File "C:\Users\ASUS\PycharmProjects\bot_frame\venv\lib\site-packages\urllib3\connectionpool.py", line 700, in urlopen
    self._prepare_proxy(conn)
  File "C:\Users\ASUS\PycharmProjects\bot_frame\venv\lib\site-packages\urllib3\connectionpool.py", line 996, in _prepare_proxy
    conn.connect()
  File "C:\Users\ASUS\PycharmProjects\bot_frame\venv\lib\site-packages\urllib3\connection.py", line 374, in connect
    self._tunnel()
  File "C:\Users\ASUS\AppData\Local\Programs\Python\Python36\lib\http\client.py", line 919, in _tunnel
    message.strip()))
OSError: Tunnel connection failed: 407 Proxy Authentication Required

During handling of the above exception, another exception occurred:

Traceback (most recent call last):
  File "C:\Users\ASUS\PycharmProjects\bot_frame\venv\lib\site-packages\requests\adapters.py", line 450, in send
    timeout=timeout
  File "C:\Users\ASUS\PycharmProjects\bot_frame\venv\lib\site-packages\urllib3\connectionpool.py", line 788, in urlopen
    method, url, error=e, _pool=self, _stacktrace=sys.exc_info()[2]
  File "C:\Users\ASUS\PycharmProjects\bot_frame\venv\lib\site-packages\urllib3\util\retry.py", line 592, in increment
    raise MaxRetryError(_pool, url, error or ResponseError(cause))
urllib3.exceptions.MaxRetryError: HTTPSConnectionPool(host='tickets.cska-hockey.ru', port=443): Max retries exceeded with url: / (Caused by ProxyError('Cannot connect to proxy.', OSError('Tunnel connection failed: 407 Proxy Authentication Required',)))

During handling of the above exception, another exception occurred:

Traceback (most recent call last):
  File "C:\Users\ASUS\PycharmProjects\bot_frame\cores_src\vis.py", line 344, in tryfunc
    func(*args)
  File "C:\Users\ASUS\PycharmProjects\bot_frame\cores_src\cores.py", line 2005, in to_try
    self.body()
  File "C:\Users\ASUS\PycharmProjects\bot_frame\cores_src\event_bot_sample.py", line 97, in body
    a_events = self.get_a_events()
  File "C:\Users\ASUS\PycharmProjects\bot_frame\bots\bot_cska-hockey.ru\event_bot.py", line 35, in get_a_events
    r = self.session.get(self.URL, headers=headers, verify=False)
  File "C:\Users\ASUS\PycharmProjects\bot_frame\cores_src\main_utils.py", line 86, in get
    return super().get(*args, **kwargs)
  File "C:\Users\ASUS\PycharmProjects\bot_frame\venv\lib\site-packages\requests\sessions.py", line 542, in get
    return self.request('GET', url, **kwargs)
  File "C:\Users\ASUS\PycharmProjects\bot_frame\venv\lib\site-packages\requests\sessions.py", line 529, in request
    resp = self.send(prep, **send_kwargs)
  File "C:\Users\ASUS\PycharmProjects\bot_frame\venv\lib\site-packages\requests\sessions.py", line 645, in send
    r = adapter.send(request, **kwargs)
  File "C:\Users\ASUS\PycharmProjects\bot_frame\venv\lib\site-packages\requests\adapters.py", line 513, in send
    raise ProxyError(e, request=request)
requests.exceptions.ProxyError: HTTPSConnectionPool(host='tickets.cska-hockey.ru', port=443): Max retries exceeded with url: / (Caused by ProxyError('Cannot connect to proxy.', OSError('Tunnel connection failed: 407 Proxy Authentication Required',)))
[39m
[33m[49m | . –ñ–¥—É 0.5—Å[39m
Sun Apr 23 20:35:29 2023 [31m[49m#1[39m –¶–°–ö–ê –• –ú—Å–∫: [31m[49mMain: HTTPSConnectionPool(host='tickets.cska-hockey.ru', port=443): Max retries exceeded with url: / (Caused by ProxyError('Cannot connect to proxy.', OSError('Tunnel connection failed: 407 Proxy Authentication Required',)))[39mSun Apr 23 20:35:30 2023 [31m[49m#1[39m –¶–°–ö–ê –• –ú—Å–∫: [31m[49mMain: HTTPSConnectionPool(host='tickets.cska-hockey.ru', port=443): Max retries exceeded with url: / (Caused by ProxyError('Cannot connect to proxy.', OSError('Tunnel connection failed: 407 Proxy Authentication Required',)))[39m
Sun Apr 23 20:36:35 2023 –ì–ª–∞–≤–Ω—ã–π: [31m[49mSub: name 'month' is not defined[39mSun Apr 23 20:36:35 2023 –ì–ª–∞–≤–Ω—ã–π: [31m[49mSub: name 'month' is not defined[39m
[31m[49mTraceback (most recent call last):
  File "C:\Users\ASUS\PycharmProjects\bot_frame\cores_src\vis.py", line 344, in tryfunc
    func(*args)
  File "C:\Users\ASUS\PycharmProjects\bot_frame\cores_src\event_bot_sample.py", line 37, in prepare_to_start
    ev, city, d, m, t = self.get_full_ev_name(event_name, page)
  File "C:\Users\ASUS\PycharmProjects\bot_frame\bots\bot_cska-hockey.ru\event_bot.py", line 80, in get_full_ev_name
    m = month[m]
NameError: name 'month' is not defined
[39m
[33m[49m | . –ñ–¥—É 0.5—Å[39m
Sun Apr 23 20:45:56 2023 –ì–ª–∞–≤–Ω—ã–π: [31m[49mEventParser: 'NoneType' object has no attribute 'release'[39mSun Apr 23 20:45:56 2023 –ì–ª–∞–≤–Ω—ã–π: [31m[49mEventParser: 'NoneType' object has no attribute 'release'[39m
[31m[49mTraceback (most recent call last):
  File "C:\Users\ASUS\PycharmProjects\bot_frame\cores_src\vis.py", line 344, in tryfunc
    func(*args)
  File "C:\Users\ASUS\PycharmProjects\bot_frame\cores_src\bot_sample_server.py", line 617, in event_parse
    start_bots(needed_events_evbot, parser_class, auto_chrtab, is_buying_bot=False)
  File "C:\Users\ASUS\PycharmProjects\bot_frame\cores_src\cores.py", line 2362, in start_bots
    tab_num = get_chrtab(BotInit.release)
AttributeError: 'NoneType' object has no attribute 'release'
[39m
[33m[49m | . –ñ–¥—É 0.5—Å[39m
